Workbook
Name ColumnTitle1: #REF!
Name RowTitleRegion1..D4: #REF!
Name RowTitleRegion2..D11: #REF!

Sheet 111 Wall Dashboard
B2: 111 Wall - Concerto Millwork - Logistics Dashboard | N2: =TODAY() -> 46217
B3: Apartment Tower - 58 units x X floors | O3: ="WEEK " &WEEKNUM(TODAY()) -> WEEK 29
B6: Total Containers | D6: Units Delivered | H6: Container Status | L6: Outlook Copy - Top 10 | O6: Coming Soon
B7: =COUNTIF('111 Wall_CTNR Schedule'!E8:E45,"<>") -> 35 | D7: =SUMIF('111 Wall_CTNR Schedule'!D8:D45,"D", '111 Wall_CTNR Schedule'!J8:J45) -> 0 | H7: PROJECTED | I7: {=SUMPRODUCT(--('111 Wall_CTNR Schedule'!D$8:D$45="PROJ"))} -> 33 | J7: =SUM(I7)/SUM($I$7:$I$12) -> 1 | L7: {="- 111W CNT "&'111 Wall_CTNR Schedule'!AR9:AR18&"("&'111 Wall_CTNR Schedule'!AY9:AY18&") FL "&'111 Wall_CTNR Schedule'!AU9:AU18&"-"&TEXT('111 Wall_CTNR Schedule'!BN9:BN18,"ddd mmm dd")&"-"&IF('111 Wall_CTNR Schedule'!BS9:BS18=FALSE,"ETA","Confirmed")} -> - 111W CNT 1(--) FL 3-Sat Sep 05-ETA
B8: Floors 3-12 Only | D8: ="Of "&SUM('111 Wall_CTNR Schedule'!J8:J45) & " Units" -> Of 622 Units | H8: LOADING | I8: {=SUMPRODUCT(--('111 Wall_CTNR Schedule'!D$8:D$45="LDG"))} -> 0 | J8: =SUM(I8)/SUM($I$7:$I$12) -> 0 | L8: - 111W CNT 2(--) FL 3-Sat Sep 05-ETA
H9: LOADED | I9: {=SUMPRODUCT(--('111 Wall_CTNR Schedule'!D$8:D$45="LDD"))} -> 0 | J9: =SUM(I9)/SUM($I$7:$I$12) -> 0 | L9: - 111W CNT 3(--) FL 3,4-Sat Sep 05-ETA
H10: ENROUTE | I10: {=SUMPRODUCT(--('111 Wall_CTNR Schedule'!D$8:D$45="ENR"))} -> 0 | J10: =SUM(I10)/SUM($I$7:$I$12) -> 0 | L10: - 111W CNT 4(--) FL 4-Sat Oct 10-ETA
B11: Transit Performance | H11: IN PORT | I11: {=SUMPRODUCT(--('111 Wall_CTNR Schedule'!D$8:D$45="INPRT"))} -> 0 | J11: =SUM(I11)/SUM($I$7:$I$12) -> 0 | L11: - 111W CNT 5(--) FL 4-Sat Oct 10-ETA
B12: Average Load Days | D12: =AVERAGE('111 Wall_CTNR Schedule'!Q8:Q40) -> 5 | H12: DELIVERED | I12: {=SUMPRODUCT(--('111 Wall_CTNR Schedule'!D$8:D$45="D"))} -> 0 | J12: =SUM(I12)/SUM($I$7:$I$12) -> 0 | L12: - 111W CNT 6(--) FL 4,5-Sat Oct 17-ETA
B13: Average Sea Transit Days | D13: =AVERAGE('111 Wall_CTNR Schedule'!U8:U40) -> 20 | L13: - 111W CNT 7(--) FL 5-Sat Oct 17-ETA
B14: Average In Port Days | D14: =AVERAGE('111 Wall_CTNR Schedule'!X8:X45) -> 4.7142857 | L14: - 111W CNT 8(--) FL 5-Sat Oct 24-ETA
B15: Total Transit Time | D15: =SUM(D12:D14) -> 29.714286 | L15: - 111W CNT 9(--) FL 5-Sat Oct 24-ETA
L16: - 111W CNT 10(--) FL 5,6-Sat Oct 31-ETA
B19: Container Schedule
B20: CTNR No. | C20: Status | D20: CTNR Code | E20: Load WK | F20: Load Date | G20: ETA NY | H20: DELIVERY | I20: Confirmed? | J20: Floor | K20: Unit Q.ty | M20: Units | N20: Notes
B21: NEXT UP
B22: {="CTN " & '111 Wall_CTNR Schedule'!E8:E45} -> CTN 1 | C22: {='111 Wall_CTNR Schedule'!D8:D45} -> PROJ | D22: {='111 Wall_CTNR Schedule'!L8:L45} -> -- | E22: {="Wk " &'111 Wall_CTNR Schedule'!F8:F45} -> Wk 32 | F22: {='111 Wall_CTNR Schedule'!P8:P45} -> 46240 | G22: {='111 Wall_CTNR Schedule'!W8:W45} -> 46265 | H22: {=TEXT('111 Wall_CTNR Schedule'!AA8:AA45,"ddd mmm dd")} -> Sat Sep 05 | I22: {=IF('111 Wall_CTNR Schedule'!AF8:AF45=FALSE,"ETA",IF('111 Wall_CTNR Schedule'!AF8:AF45=TRUE,"Confirmed"))} -> ETA | J22: {="FL " & '111 Wall_CTNR Schedule'!H8:H45} -> FL 3 | K22: {='111 Wall_CTNR Schedule'!J8:J45& "x"} -> 20x | M22: {='111 Wall_CTNR Schedule'!I8:I45} -> 301:313,315:321 | N22: {='111 Wall_CTNR Schedule'!AK8:AK45} -> 30
B23: CTN 2 | C23: PROJ | D23: -- | E23: Wk 32 | F23: 46240 | G23: 46265 | H23: Sat Sep 05 | I23: ETA | J23: FL 3 | K23: 20x | M23: 322:333,335:342 | N23: 30
B24: CTN 3 | C24: PROJ | D24: -- | E24: Wk 32 | F24: 46240 | G24: 46265 | H24: Sat Sep 05 | I24: ETA | J24: FL 3,4 | K24: 20x | M24: 343:349,352:354,356:358,401:407 | N24: 30
B25: CTN 4 | C25: PROJ | D25: -- | E25: Wk 37 | F25: 46275 | G25: 46300 | H25: Sat Oct 10 | I25: ETA | J25: FL 4 | K25: 18x | M25: 408:425 | N25: 30
B26: CTN 5 | C26: PROJ | D26: -- | E26: Wk 37 | F26: 46275 | G26: 46300 | H26: Sat Oct 10 | I26: ETA | J26: FL 4 | K26: 18x | M26: 426:443 | N26: 30
B27: CTN 6 | C27: PROJ | D27: -- | E27: Wk 38 | F27: 46282 | G27: 46307 | H27: Sat Oct 17 | I27: ETA | J27: FL 4,5 | K27: 16x | M27: 444:449,452:458,501:503 | N27: 30
B28: CTN 7 | C28: PROJ | D28: -- | E28: Wk 38 | F28: 46282 | G28: 46307 | H28: Sat Oct 17 | I28: ETA | J28: FL 5 | K28: 18x | M28: 504:521 | N28: 30
B29: CTN 8 | C29: PROJ | D29: -- | E29: Wk 39 | F29: 46289 | G29: 46314 | H29: Sat Oct 24 | I29: ETA | J29: FL 5 | K29: 18x | M29: 522:539 | N29: 30
B30: CTN 9 | C30: PROJ | D30: -- | E30: Wk 39 | F30: 46289 | G30: 46314 | H30: Sat Oct 24 | I30: ETA | J30: FL 5 | K30: 16x | M30: 540:549,552:557 | N30: 30
B31: CTN 10 | C31: PROJ | D31: -- | E31: Wk 40 | F31: 46296 | G31: 46321 | H31: Sat Oct 31 | I31: ETA | J31: FL 5,6 | K31: 18x | M31: 558,601:617 | N31: 30
B32: CTN 11 | C32: PROJ | D32: -- | E32: Wk 40 | F32: 46296 | G32: 46321 | H32: Sat Oct 31 | I32: ETA | J32: FL 6 | K32: 18x | M32: 618:635 | N32: 30
B33: CTN 12 | C33: PROJ | D33: -- | E33: Wk 41 | F33: 46303 | G33: 46328 | H33: Sat Nov 07 | I33: ETA | J33: FL 6 | K33: 16x | M33: 636:649,652:653 | N33: 30
B34: CTN 13 | C34: PROJ | D34: -- | E34: Wk 41 | F34: 46303 | G34: 46328 | H34: Sat Nov 07 | I34: ETA | J34: FL 6,7 | K34: 18x | M34: 654:658,701:713 | N34: 30
... B54: CTN H1 | C54: PROJ | D54: -- | E54: Wk 51 | F54: 46373 | G54: 46398 | H54: Sat Jan 16 | I54: ETA | J54: FL 3:10 | K54: 16x | M54: 350:351,450:451,550:551,650:651,750:751,850:851,950:951,1050:1051 | N54: 30
B55: CTN 0 | C55: 0 | D55: 0 | E55: Wk 0 | F55: 0 | G55: 0 | H55: Sat Jan 00 | I55: FALSE | J55: FL 0 | K55: 0x | M55: 0 | N55: 0
B56: CTN 0 | C56: 0 | D56: 0 | E56: Wk 0 | F56: 0 | G56: 0 | H56: Sat Jan 00 | I56: FALSE | J56: FL 0 | K56: 0x | M56: 0 | N56: 0
B57: CTN | C57: 0 | D57: 0 | E57: Wk | F57: 0 | G57: 0 | H57: Sat Jan 00 | I57: ETA | J57: FL | K57: x | M57: 0 | N57: 0
B58: CTN | C58: 0 | D58: 0 | E58: Wk | F58: 0 | G58: 0 | H58: Sat Jan 00 | I58: ETA | J58: FL | K58: x | M58: 0 | N58: 0
B59: CTN | C59: 0 | D59: 0 | E59: Wk | F59: 0 | G59: 0 | H59: Sat Jan 00 | I59: ETA | J59: FL | K59: x | M59: 0 | N59: 0

Sheet 111 Wall_Building Matrix
B2: 111W -BUILDING MATRIX
B3: KITCHEN TYPE & STATUS | M3: Top-Down | P3: = Flip the Building
AZ4: HOIST
B5: UNITS | C5: 01 | D5: 02 | E5: 03 | F5: 04 | G5: 05 | H5: 06 | I5: 07 | J5: 08 | K5: 09 | L5: 10 | M5: 11 | N5: 12 | O5: 13 | P5: 14 | Q5: 15 | R5: 16 | S5: 17 | T5: 18 | U5: 19 | V5: 20 | W5: 21 | X5: 22 | Y5: 23 | Z5: 24 | AA5: 25 | AB5: 26 | AC5: 27 | AD5: 28 | AE5: 29 | AF5: 30 | AG5: 31 | AH5: 32 | AI5: 33 | AJ5: 34 | AK5: 35 | AL5: 36 | AM5: 37 | AN5: 38 | AO5: 39 | AP5: 40 | AQ5: 41 | AR5: 42 | AS5: 43 | AT5: 44 | AU5: 45 | AV5: 46 | AW5: 47 | AX5: 48 | AY5: 49 | AZ5: 50 | BA5: 51 | BB5: 52 | BC5: 53 | BD5: 54 | BE5: 55 | BF5: 56 | BG5: 57 | BH5: 58 | BJ5: Floor-by-Floor Status
B6: FLOOR
C7: {=$B8*100+C$5:BH$5} -> 2901 | D7: 2902 | E7: 2903 | F7: 2904 | G7: 2905 | H7: 2906 | I7: 2907 | J7: 2908 | K7: 2909 | L7: 2910 | M7: 2911 | N7: 2912 | O7: 2913 | P7: 2914 | Q7: 2915 | R7: 2916 | S7: 2917 | T7: 2918 | U7: 2919 | V7: 2920 | W7: 2921 | X7: 2922 | Y7: 2923 | Z7: 2924 | AA7: 2925 | AB7: 2926 | AC7: 2927 | AD7: 2928 | AE7: 2929 | AF7: 2930 | AG7: 2931 | AH7: 2932 | AI7: 2933 | AJ7: 2934 | AK7: 2935 | AL7: 2936 | AM7: 2937 | AN7: 2938 | AO7: 2939 | AP7: 2940 | AQ7: 2941 | AR7: 2942 | AS7: 2943 | AT7: 2944 | AU7: 2945 | AV7: 2946 | AW7: 2947 | AX7: 2948 | AY7: 2949 | AZ7: 2950 | BA7: 2951 | BB7: 2952 | BC7: 2953 | BD7: 2954 | BE7: 2955 | BF7: 2956 | BG7: 2957 | BH7: 2958 | BJ7: =B8&"th FLOOR" -> 29th FLOOR
B8: {=_xlfn.LET(_xlpm.s,_xlfn.SEQUENCE(79),_xlpm.k,(_xlpm.s-1)/3,IF(MOD(_xlpm.s-1,3)=0,IF($M$3="Top-Down",29-_xlpm.k,3+_xlpm.k),""))} -> 29 | C8: {=_xlfn.XLOOKUP(C7:BH7,'[1]111W_BUILDING MATRIX'!$B$8:$B$600,'[1]111W_BUILDING MATRIX'!$E$8:$E$600,"--")} -> -- | D8: -- | E8: -- | F8: -- | G8: -- | H8: -- | I8: -- | J8: -- | K8: -- | L8: -- | M8: -- | N8: -- | O8: -- | P8: -- | Q8: -- | R8: -- | S8: -- | T8: -- | U8: -- | V8: -- | W8: -- | X8: -- | Y8: -- | Z8: -- | AA8: -- | AB8: -- | AC8: -- | AD8: -- | AE8: -- | AF8: -- | AG8: -- | AH8: -- | AI8: -- | AJ8: -- | AK8: -- | AL8: -- | AM8: -- | AN8: -- | AO8: -- | AP8: -- | AQ8: -- | AR8: -- | AS8: -- | AT8: -- | AU8: -- | AV8: -- | AW8: -- | AX8: -- | AY8: -- | AZ8: -- | BA8: -- | BB8: -- | BC8: -- | BD8: -- | BE8: -- | BF8: -- | BG8: -- | BH8: -- | BJ8: =COUNTIF(C9:BH9, "D") -> 0 | BK8: KITCHENS DELIVERED out of | BN8: =COUNTIF(C9:BH9,"<>--") -> 0 | BO8: =BJ8/BN8 -> #DIV/0!
C9: {=_xlfn.XLOOKUP(C7:BH7,'[1]111W_BUILDING MATRIX'!$B$8:$B$600,'[1]111W_BUILDING MATRIX'!$H$8:$H$600,"--")} -> -- | D9: -- | E9: -- | F9: -- | G9: -- | H9: -- | I9: -- | J9: -- | K9: -- | L9: -- | M9: -- | N9: -- | O9: -- | P9: -- | Q9: -- | R9: -- | S9: -- | T9: -- | U9: -- | V9: -- | W9: -- | X9: -- | Y9: -- | Z9: -- | AA9: -- | AB9: -- | AC9: -- | AD9: -- | AE9: -- | AF9: -- | AG9: -- | AH9: -- | AI9: -- | AJ9: -- | AK9: -- | AL9: -- | AM9: -- | AN9: -- | AO9: -- | AP9: -- | AQ9: -- | AR9: -- | AS9: -- | AT9: -- | AU9: -- | AV9: -- | AW9: -- | AX9: -- | AY9: -- | AZ9: -- | BA9: -- | BB9: -- | BC9: -- | BD9: -- | BE9: -- | BF9: -- | BG9: -- | BH9: --
C10: {=$B11*100+C$5:BH$5} -> 2801 | D10: 2802 | E10: 2803 | F10: 2804 | G10: 2805 | H10: 2806 | I10: 2807 | J10: 2808 | K10: 2809 | L10: 2810 | M10: 2811 | N10: 2812 | O10: 2813 | P10: 2814 | Q10: 2815 | R10: 2816 | S10: 2817 | T10: 2818 | U10: 2819 | V10: 2820 | W10: 2821 | X10: 2822 | Y10: 2823 | Z10: 2824 | AA10: 2825 | AB10: 2826 | AC10: 2827 | AD10: 2828 | AE10: 2829 | AF10: 2830 | AG10: 2831 | AH10: 2832 | AI10: 2833 | AJ10: 2834 | AK10: 2835 | AL10: 2836 | AM10: 2837 | AN10: 2838 | AO10: 2839 | AP10: 2840 | AQ10: 2841 | AR10: 2842 | AS10: 2843 | AT10: 2844 | AU10: 2845 | AV10: 2846 | AW10: 2847 | AX10: 2848 | AY10: 2849 | AZ10: 2850 | BA10: 2851 | BB10: 2852 | BC10: 2853 | BD10: 2854 | BE10: 2855 | BF10: 2856 | BG10: 2857 | BH10: 2858 | BJ10: =B11&"th FLOOR" -> 28th FLOOR
B11: 28 | C11: {=_xlfn.XLOOKUP(C10:BH10,'[1]111W_BUILDING MATRIX'!$B$8:$B$600,'[1]111W_BUILDING MATRIX'!$E$8:$E$600,"--")} -> -- | D11: -- | E11: -- | F11: -- | G11: -- | H11: -- | I11: -- | J11: -- | K11: -- | L11: -- | M11: -- | N11: -- | O11: -- | P11: -- | Q11: -- | R11: -- | S11: -- | T11: -- | U11: -- | V11: -- | W11: -- | X11: -- | Y11: -- | Z11: -- | AA11: -- | AB11: -- | AC11: -- | AD11: -- | AE11: -- | AF11: -- | AG11: -- | AH11: -- | AI11: -- | AJ11: -- | AK11: -- | AL11: -- | AM11: -- | AN11: -- | AO11: -- | AP11: -- | AQ11: -- | AR11: -- | AS11: -- | AT11: -- | AU11: -- | AV11: -- | AW11: -- | AX11: -- | AY11: -- | AZ11: -- | BA11: -- | BB11: -- | BC11: -- | BD11: -- | BE11: -- | BF11: -- | BG11: -- | BH11: -- | BJ11: =COUNTIF(C12:BH12, "D") -> 0 | BK11: KITCHENS DELIVERED out of | BN11: =COUNTIF(C12:BH12,"<>--") -> 0 | BO11: =BJ11/BN11 -> #DIV/0!
C12: {=_xlfn.XLOOKUP(C10:BH10,'[1]111W_BUILDING MATRIX'!$B$8:$B$600,'[1]111W_BUILDING MATRIX'!$H$8:$H$600,"--")} -> -- | D12: -- | E12: -- | F12: -- | G12: -- | H12: -- | I12: -- | J12: -- | K12: -- | L12: -- | M12: -- | N12: -- | O12: -- | P12: -- | Q12: -- | R12: -- | S12: -- | T12: -- | U12: -- | V12: -- | W12: -- | X12: -- | Y12: -- | Z12: -- | AA12: -- | AB12: -- | AC12: -- | AD12: -- | AE12: -- | AF12: -- | AG12: -- | AH12: -- | AI12: -- | AJ12: -- | AK12: -- | AL12: -- | AM12: -- | AN12: -- | AO12: -- | AP12: -- | AQ12: -- | AR12: -- | AS12: -- | AT12: -- | AU12: -- | AV12: -- | AW12: -- | AX12: -- | AY12: -- | AZ12: -- | BA12: -- | BB12: -- | BC12: -- | BD12: -- | BE12: -- | BF12: -- | BG12: -- | BH12: --
C13: {=$B14*100+C$5:BH$5} -> 2701 | D13: 2702 | E13: 2703 | F13: 2704 | G13: 2705 | H13: 2706 | I13: 2707 | J13: 2708 | K13: 2709 | L13: 2710 | M13: 2711 | N13: 2712 | O13: 2713 | P13: 2714 | Q13: 2715 | R13: 2716 | S13: 2717 | T13: 2718 | U13: 2719 | V13: 2720 | W13: 2721 | X13: 2722 | Y13: 2723 | Z13: 2724 | AA13: 2725 | AB13: 2726 | AC13: 2727 | AD13: 2728 | AE13: 2729 | AF13: 2730 | AG13: 2731 | AH13: 2732 | AI13: 2733 | AJ13: 2734 | AK13: 2735 | AL13: 2736 | AM13: 2737 | AN13: 2738 | AO13: 2739 | AP13: 2740 | AQ13: 2741 | AR13: 2742 | AS13: 2743 | AT13: 2744 | AU13: 2745 | AV13: 2746 | AW13: 2747 | AX13: 2748 | AY13: 2749 | AZ13: 2750 | BA13: 2751 | BB13: 2752 | BC13: 2753 | BD13: 2754 | BE13: 2755 | BF13: 2756 | BG13: 2757 | BH13: 2758 | BJ13: =B14&"th FLOOR" -> 27th FLOOR
B14: 27 | C14: {=_xlfn.XLOOKUP(C13:BH13,'[1]111W_BUILDING MATRIX'!$B$8:$B$600,'[1]111W_BUILDING MATRIX'!$E$8:$E$600,"--")} -> -- | D14: -- | E14: -- | F14: -- | G14: -- | H14: -- | I14: -- | J14: -- | K14: -- | L14: -- | M14: -- | N14: -- | O14: -- | P14: -- | Q14: -- | R14: -- | S14: -- | T14: -- | U14: -- | V14: -- | W14: -- | X14: -- | Y14: -- | Z14: -- | AA14: -- | AB14: -- | AC14: -- | AD14: -- | AE14: -- | AF14: -- | AG14: -- | AH14: -- | AI14: -- | AJ14: -- | AK14: -- | AL14: -- | AM14: -- | AN14: -- | AO14: -- | AP14: -- | AQ14: -- | AR14: -- | AS14: -- | AT14: -- | AU14: -- | AV14: -- | AW14: -- | AX14: -- | AY14: -- | AZ14: -- | BA14: -- | BB14: -- | BC14: -- | BD14: -- | BE14: -- | BF14: -- | BG14: -- | BH14: -- | BJ14: =COUNTIF(C15:BH15, "D") -> 0 | BK14: KITCHENS DELIVERED out of | BN14: =COUNTIF(C15:BH15,"<>--") -> 0 | BO14: =BJ14/BN14 -> #DIV/0!
C15: {=_xlfn.XLOOKUP(C13:BH13,'[1]111W_BUILDING MATRIX'!$B$8:$B$600,'[1]111W_BUILDING MATRIX'!$H$8:$H$600,"--")} -> -- | D15: -- | E15: -- | F15: -- | G15: -- | H15: -- | I15: -- | J15: -- | K15: -- | L15: -- | M15: -- | N15: -- | O15: -- | P15: -- | Q15: -- | R15: -- | S15: -- | T15: -- | U15: -- | V15: -- | W15: -- | X15: -- | Y15: -- | Z15: -- | AA15: -- | AB15: -- | AC15: -- | AD15: -- | AE15: -- | AF15: -- | AG15: -- | AH15: -- | AI15: -- | AJ15: -- | AK15: -- | AL15: -- | AM15: -- | AN15: -- | AO15: -- | AP15: -- | AQ15: -- | AR15: -- | AS15: -- | AT15: -- | AU15: -- | AV15: -- | AW15: -- | AX15: -- | AY15: -- | AZ15: -- | BA15: -- | BB15: -- | BC15: -- | BD15: -- | BE15: -- | BF15: -- | BG15: -- | BH15: --
C16: {=$B17*100+C$5:BH$5} -> 2601 | D16: 2602 | E16: 2603 | F16: 2604 | G16: 2605 | H16: 2606 | I16: 2607 | J16: 2608 | K16: 2609 | L16: 2610 | M16: 2611 | N16: 2612 | O16: 2613 | P16: 2614 | Q16: 2615 | R16: 2616 | S16: 2617 | T16: 2618 | U16: 2619 | V16: 2620 | W16: 2621 | X16: 2622 | Y16: 2623 | Z16: 2624 | AA16: 2625 | AB16: 2626 | AC16: 2627 | AD16: 2628 | AE16: 2629 | AF16: 2630 | AG16: 2631 | AH16: 2632 | AI16: 2633 | AJ16: 2634 | AK16: 2635 | AL16: 2636 | AM16: 2637 | AN16: 2638 | AO16: 2639 | AP16: 2640 | AQ16: 2641 | AR16: 2642 | AS16: 2643 | AT16: 2644 | AU16: 2645 | AV16: 2646 | AW16: 2647 | AX16: 2648 | AY16: 2649 | AZ16: 2650 | BA16: 2651 | BB16: 2652 | BC16: 2653 | BD16: 2654 | BE16: 2655 | BF16: 2656 | BG16: 2657 | BH16: 2658 | BJ16: =B17&"th FLOOR" -> 26th FLOOR
B17: 26 | C17: {=_xlfn.XLOOKUP(C16:BH16,'[1]111W_BUILDING MATRIX'!$B$8:$B$600,'[1]111W_BUILDING MATRIX'!$E$8:$E$600,"--")} -> -- | D17: -- | E17: -- | F17: -- | G17: -- | H17: -- | I17: -- | J17: -- | K17: -- | L17: -- | M17: -- | N17: -- | O17: -- | P17: -- | Q17: -- | R17: -- | S17: -- | T17: -- | U17: -- | V17: -- | W17: -- | X17: -- | Y17: -- | Z17: -- | AA17: -- | AB17: -- | AC17: -- | AD17: -- | AE17: -- | AF17: -- | AG17: -- | AH17: -- | AI17: -- | AJ17: -- | AK17: -- | AL17: -- | AM17: -- | AN17: -- | AO17: -- | AP17: -- | AQ17: -- | AR17: -- | AS17: -- | AT17: -- | AU17: -- | AV17: -- | AW17: -- | AX17: -- | AY17: -- | AZ17: -- | BA17: -- | BB17: -- | BC17: -- | BD17: -- | BE17: -- | BF17: -- | BG17: -- | BH17: -- | BJ17: =COUNTIF(C18:BH18, "D") -> 0 | BK17: KITCHENS DELIVERED out of | BN17: =COUNTIF(C18:BH18,"<>--") -> 0 | BO17: =BJ17/BN17 -> #DIV/0!
C18: {=_xlfn.XLOOKUP(C16:BH16,'[1]111W_BUILDING MATRIX'!$B$8:$B$600,'[1]111W_BUILDING MATRIX'!$H$8:$H$600,"--")} -> -- | D18: -- | E18: -- | F18: -- | G18: -- | H18: -- | I18: -- | J18: -- | K18: -- | L18: -- | M18: -- | N18: -- | O18: -- | P18: -- | Q18: -- | R18: -- | S18: -- | T18: -- | U18: -- | V18: -- | W18: -- | X18: -- | Y18: -- | Z18: -- | AA18: -- | AB18: -- | AC18: -- | AD18: -- | AE18: -- | AF18: -- | AG18: -- | AH18: -- | AI18: -- | AJ18: -- | AK18: -- | AL18: -- | AM18: -- | AN18: -- | AO18: -- | AP18: -- | AQ18: -- | AR18: -- | AS18: -- | AT18: -- | AU18: -- | AV18: -- | AW18: -- | AX18: -- | AY18: -- | AZ18: -- | BA18: -- | BB18: -- | BC18: -- | BD18: -- | BE18: -- | BF18: -- | BG18: -- | BH18: --
C19: {=$B20*100+C$5:BH$5} -> 2501 | D19: 2502 | E19: 2503 | F19: 2504 | G19: 2505 | H19: 2506 | I19: 2507 | J19: 2508 | K19: 2509 | L19: 2510 | M19: 2511 | N19: 2512 | O19: 2513 | P19: 2514 | Q19: 2515 | R19: 2516 | S19: 2517 | T19: 2518 | U19: 2519 | V19: 2520 | W19: 2521 | X19: 2522 | Y19: 2523 | Z19: 2524 | AA19: 2525 | AB19: 2526 | AC19: 2527 | AD19: 2528 | AE19: 2529 | AF19: 2530 | AG19: 2531 | AH19: 2532 | AI19: 2533 | AJ19: 2534 | AK19: 2535 | AL19: 2536 | AM19: 2537 | AN19: 2538 | AO19: 2539 | AP19: 2540 | AQ19: 2541 | AR19: 2542 | AS19: 2543 | AT19: 2544 | AU19: 2545 | AV19: 2546 | AW19: 2547 | AX19: 2548 | AY19: 2549 | AZ19: 2550 | BA19: 2551 | BB19: 2552 | BC19: 2553 | BD19: 2554 | BE19: 2555 | BF19: 2556 | BG19: 2557 | BH19: 2558 | BJ19: =B20&"th FLOOR" -> 25th FLOOR
B20: 25 | C20: {=_xlfn.XLOOKUP(C19:BH19,'[1]111W_BUILDING MATRIX'!$B$8:$B$600,'[1]111W_BUILDING MATRIX'!$E$8:$E$600,"--")} -> -- | D20: -- | E20: -- | F20: -- | G20: -- | H20: -- | I20: -- | J20: -- | K20: -- | L20: -- | M20: -- | N20: -- | O20: -- | P20: -- | Q20: -- | R20: -- | S20: -- | T20: -- | U20: -- | V20: -- | W20: -- | X20: -- | Y20: -- | Z20: -- | AA20: -- | AB20: -- | AC20: -- | AD20: -- | AE20: -- | AF20: -- | AG20: -- | AH20: -- | AI20: -- | AJ20: -- | AK20: -- | AL20: -- | AM20: -- | AN20: -- | AO20: -- | AP20: -- | AQ20: -- | AR20: -- | AS20: -- | AT20: -- | AU20: -- | AV20: -- | AW20: -- | AX20: -- | AY20: -- | AZ20: -- | BA20: -- | BB20: -- | BC20: -- | BD20: -- | BE20: -- | BF20: -- | BG20: -- | BH20: -- | BJ20: =COUNTIF(C21:BH21, "D") -> 0 | BK20: KITCHENS DELIVERED out of | BN20: =COUNTIF(C21:BH21,"<>--") -> 0 | BO20: =BJ20/BN20 -> #DIV/0!
C21: {=_xlfn.XLOOKUP(C19:BH19,'[1]111W_BUILDING MATRIX'!$B$8:$B$600,'[1]111W_BUILDING MATRIX'!$H$8:$H$600,"--")} -> -- | D21: -- | E21: -- | F21: -- | G21: -- | H21: -- | I21: -- | J21: -- | K21: -- | L21: -- | M21: -- | N21: -- | O21: -- | P21: -- | Q21: -- | R21: -- | S21: -- | T21: -- | U21: -- | V21: -- | W21: -- | X21: -- | Y21: -- | Z21: -- | AA21: -- | AB21: -- | AC21: -- | AD21: -- | AE21: -- | AF21: -- | AG21: -- | AH21: -- | AI21: -- | AJ21: -- | AK21: -- | AL21: -- | AM21: -- | AN21: -- | AO21: -- | AP21: -- | AQ21: -- | AR21: -- | AS21: -- | AT21: -- | AU21: -- | AV21: -- | AW21: -- | AX21: -- | AY21: -- | AZ21: -- | BA21: -- | BB21: -- | BC21: -- | BD21: -- | BE21: -- | BF21: -- | BG21: -- | BH21: --
C22: {=$B23*100+C$5:BH$5} -> 2401 | D22: 2402 | E22: 2403 | F22: 2404 | G22: 2405 | H22: 2406 | I22: 2407 | J22: 2408 | K22: 2409 | L22: 2410 | M22: 2411 | N22: 2412 | O22: 2413 | P22: 2414 | Q22: 2415 | R22: 2416 | S22: 2417 | T22: 2418 | U22: 2419 | V22: 2420 | W22: 2421 | X22: 2422 | Y22: 2423 | Z22: 2424 | AA22: 2425 | AB22: 2426 | AC22: 2427 | AD22: 2428 | AE22: 2429 | AF22: 2430 | AG22: 2431 | AH22: 2432 | AI22: 2433 | AJ22: 2434 | AK22: 2435 | AL22: 2436 | AM22: 2437 | AN22: 2438 | AO22: 2439 | AP22: 2440 | AQ22: 2441 | AR22: 2442 | AS22: 2443 | AT22: 2444 | AU22: 2445 | AV22: 2446 | AW22: 2447 | AX22: 2448 | AY22: 2449 | AZ22: 2450 | BA22: 2451 | BB22: 2452 | BC22: 2453 | BD22: 2454 | BE22: 2455 | BF22: 2456 | BG22: 2457 | BH22: 2458 | BJ22: =B23&"th FLOOR" -> 24th FLOOR
B23: 24 | C23: {=_xlfn.XLOOKUP(C22:BH22,'[1]111W_BUILDING MATRIX'!$B$8:$B$600,'[1]111W_BUILDING MATRIX'!$E$8:$E$600,"--")} -> -- | D23: -- | E23: -- | F23: -- | G23: -- | H23: -- | I23: -- | J23: -- | K23: -- | L23: -- | M23: -- | N23: -- | O23: -- | P23: -- | Q23: -- | R23: -- | S23: -- | T23: -- | U23: -- | V23: -- | W23: -- | X23: -- | Y23: -- | Z23: -- | AA23: -- | AB23: -- | AC23: -- | AD23: -- | AE23: -- | AF23: -- | AG23: -- | AH23: -- | AI23: -- | AJ23: -- | AK23: -- | AL23: -- | AM23: -- | AN23: -- | AO23: -- | AP23: -- | AQ23: -- | AR23: -- | AS23: -- | AT23: -- | AU23: -- | AV23: -- | AW23: -- | AX23: -- | AY23: -- | AZ23: -- | BA23: -- | BB23: -- | BC23: -- | BD23: -- | BE23: -- | BF23: -- | BG23: -- | BH23: -- | BJ23: =COUNTIF(C24:BH24, "D") -> 0 | BK23: KITCHENS DELIVERED out of | BN23: =COUNTIF(C24:BH24,"<>--") -> 0 | BO23: =BJ23/BN23 -> #DIV/0!
C24: {=_xlfn.XLOOKUP(C22:BH22,'[1]111W_BUILDING MATRIX'!$B$8:$B$600,'[1]111W_BUILDING MATRIX'!$H$8:$H$600,"--")} -> -- | D24: -- | E24: -- | F24: -- | G24: -- | H24: -- | I24: -- | J24: -- | K24: -- | L24: -- | M24: -- | N24: -- | O24: -- | P24: -- | Q24: -- | R24: -- | S24: -- | T24: -- | U24: -- | V24: -- | W24: -- | X24: -- | Y24: -- | Z24: -- | AA24: -- | AB24: -- | AC24: -- | AD24: -- | AE24: -- | AF24: -- | AG24: -- | AH24: -- | AI24: -- | AJ24: -- | AK24: -- | AL24: -- | AM24: -- | AN24: -- | AO24: -- | AP24: -- | AQ24: -- | AR24: -- | AS24: -- | AT24: -- | AU24: -- | AV24: -- | AW24: -- | AX24: -- | AY24: -- | AZ24: -- | BA24: -- | BB24: -- | BC24: -- | BD24: -- | BE24: -- | BF24: -- | BG24: -- | BH24: --
C25: {=$B26*100+C$5:BH$5} -> 2301 | D25: 2302 | E25: 2303 | F25: 2304 | G25: 2305 | H25: 2306 | I25: 2307 | J25: 2308 | K25: 2309 | L25: 2310 | M25: 2311 | N25: 2312 | O25: 2313 | P25: 2314 | Q25: 2315 | R25: 2316 | S25: 2317 | T25: 2318 | U25: 2319 | V25: 2320 | W25: 2321 | X25: 2322 | Y25: 2323 | Z25: 2324 | AA25: 2325 | AB25: 2326 | AC25: 2327 | AD25: 2328 | AE25: 2329 | AF25: 2330 | AG25: 2331 | AH25: 2332 | AI25: 2333 | AJ25: 2334 | AK25: 2335 | AL25: 2336 | AM25: 2337 | AN25: 2338 | AO25: 2339 | AP25: 2340 | AQ25: 2341 | AR25: 2342 | AS25: 2343 | AT25: 2344 | AU25: 2345 | AV25: 2346 | AW25: 2347 | AX25: 2348 | AY25: 2349 | AZ25: 2350 | BA25: 2351 | BB25: 2352 | BC25: 2353 | BD25: 2354 | BE25: 2355 | BF25: 2356 | BG25: 2357 | BH25: 2358 | BJ25: =B26&"rd FLOOR" -> 23rd FLOOR
B26: 23 | C26: {=_xlfn.XLOOKUP(C25:BH25,'[1]111W_BUILDING MATRIX'!$B$8:$B$600,'[1]111W_BUILDING MATRIX'!$E$8:$E$600,"--")} -> -- | D26: -- | E26: -- | F26: -- | G26: -- | H26: -- | I26: -- | J26: -- | K26: -- | L26: -- | M26: -- | N26: -- | O26: -- | P26: -- | Q26: -- | R26: -- | S26: -- | T26: -- | U26: -- | V26: -- | W26: -- | X26: -- | Y26: -- | Z26: -- | AA26: -- | AB26: -- | AC26: -- | AD26: -- | AE26: -- | AF26: -- | AG26: -- | AH26: -- | AI26: -- | AJ26: -- | AK26: -- | AL26: -- | AM26: -- | AN26: -- | AO26: -- | AP26: -- | AQ26: -- | AR26: -- | AS26: -- | AT26: -- | AU26: -- | AV26: -- | AW26: -- | AX26: -- | AY26: -- | AZ26: -- | BA26: -- | BB26: -- | BC26: -- | BD26: -- | BE26: -- | BF26: -- | BG26: -- | BH26: -- | BJ26: =COUNTIF(C27:BH27, "D") -> 0 | BK26: KITCHENS DELIVERED out of | BN26: =COUNTIF(C27:BH27,"<>--") -> 0 | BO26: =BJ26/BN26 -> #DIV/0!
C27: {=_xlfn.XLOOKUP(C25:BH25,'[1]111W_BUILDING MATRIX'!$B$8:$B$600,'[1]111W_BUILDING MATRIX'!$H$8:$H$600,"--")} -> -- | D27: -- | E27: -- | F27: -- | G27: -- | H27: -- | I27: -- | J27: -- | K27: -- | L27: -- | M27: -- | N27: -- | O27: -- | P27: -- | Q27: -- | R27: -- | S27: -- | T27: -- | U27: -- | V27: -- | W27: -- | X27: -- | Y27: -- | Z27: -- | AA27: -- | AB27: -- | AC27: -- | AD27: -- | AE27: -- | AF27: -- | AG27: -- | AH27: -- | AI27: -- | AJ27: -- | AK27: -- | AL27: -- | AM27: -- | AN27: -- | AO27: -- | AP27: -- | AQ27: -- | AR27: -- | AS27: -- | AT27: -- | AU27: -- | AV27: -- | AW27: -- | AX27: -- | AY27: -- | AZ27: -- | BA27: -- | BB27: -- | BC27: -- | BD27: -- | BE27: -- | BF27: -- | BG27: -- | BH27: --
C28: {=$B29*100+C$5:BH$5} -> 2201 | D28: 2202 | E28: 2203 | F28: 2204 | G28: 2205 | H28: 2206 | I28: 2207 | J28: 2208 | K28: 2209 | L28: 2210 | M28: 2211 | N28: 2212 | O28: 2213 | P28: 2214 | Q28: 2215 | R28: 2216 | S28: 2217 | T28: 2218 | U28: 2219 | V28: 2220 | W28: 2221 | X28: 2222 | Y28: 2223 | Z28: 2224 | AA28: 2225 | AB28: 2226 | AC28: 2227 | AD28: 2228 | AE28: 2229 | AF28: 2230 | AG28: 2231 | AH28: 2232 | AI28: 2233 | AJ28: 2234 | AK28: 2235 | AL28: 2236 | AM28: 2237 | AN28: 2238 | AO28: 2239 | AP28: 2240 | AQ28: 2241 | AR28: 2242 | AS28: 2243 | AT28: 2244 | AU28: 2245 | AV28: 2246 | AW28: 2247 | AX28: 2248 | AY28: 2249 | AZ28: 2250 | BA28: 2251 | BB28: 2252 | BC28: 2253 | BD28: 2254 | BE28: 2255 | BF28: 2256 | BG28: 2257 | BH28: 2258 | BJ28: =B29&"nd FLOOR" -> 22nd FLOOR
B29: 22 | C29: {=_xlfn.XLOOKUP(C28:BH28,'[1]111W_BUILDING MATRIX'!$B$8:$B$600,'[1]111W_BUILDING MATRIX'!$E$8:$E$600,"--")} -> -- | D29: -- | E29: -- | F29: -- | G29: -- | H29: -- | I29: -- | J29: -- | K29: -- | L29: -- | M29: -- | N29: -- | O29: -- | P29: -- | Q29: -- | R29: -- | S29: -- | T29: -- | U29: -- | V29: -- | W29: -- | X29: -- | Y29: -- | Z29: -- | AA29: -- | AB29: -- | AC29: -- | AD29: -- | AE29: -- | AF29: -- | AG29: -- | AH29: -- | AI29: -- | AJ29: -- | AK29: -- | AL29: -- | AM29: -- | AN29: -- | AO29: -- | AP29: -- | AQ29: -- | AR29: -- | AS29: -- | AT29: -- | AU29: -- | AV29: -- | AW29: -- | AX29: -- | AY29: -- | AZ29: -- | BA29: -- | BB29: -- | BC29: -- | BD29: -- | BE29: -- | BF29: -- | BG29: -- | BH29: -- | BJ29: =COUNTIF(C30:BH30, "D") -> 0 | BK29: KITCHENS DELIVERED out of | BN29: =COUNTIF(C30:BH30,"<>--") -> 0 | BO29: =BJ29/BN29 -> #DIV/0!
C30: {=_xlfn.XLOOKUP(C28:BH28,'[1]111W_BUILDING MATRIX'!$B$8:$B$600,'[1]111W_BUILDING MATRIX'!$H$8:$H$600,"--")} -> -- | D30: -- | E30: -- | F30: -- | G30: -- | H30: -- | I30: -- | J30: -- | K30: -- | L30: -- | M30: -- | N30: -- | O30: -- | P30: -- | Q30: -- | R30: -- | S30: -- | T30: -- | U30: -- | V30: -- | W30: -- | X30: -- | Y30: -- | Z30: -- | AA30: -- | AB30: -- | AC30: -- | AD30: -- | AE30: -- | AF30: -- | AG30: -- | AH30: -- | AI30: -- | AJ30: -- | AK30: -- | AL30: -- | AM30: -- | AN30: -- | AO30: -- | AP30: -- | AQ30: -- | AR30: -- | AS30: -- | AT30: -- | AU30: -- | AV30: -- | AW30: -- | AX30: -- | AY30: -- | AZ30: -- | BA30: -- | BB30: -- | BC30: -- | BD30: -- | BE30: -- | BF30: -- | BG30: -- | BH30: --
C31: {=$B32*100+C$5:BH$5} -> 2101 | D31: 2102 | E31: 2103 | F31: 2104 | G31: 2105 | H31: 2106 | I31: 2107 | J31: 2108 | K31: 2109 | L31: 2110 | M31: 2111 | N31: 2112 | O31: 2113 | P31: 2114 | Q31: 2115 | R31: 2116 | S31: 2117 | T31: 2118 | U31: 2119 | V31: 2120 | W31: 2121 | X31: 2122 | Y31: 2123 | Z31: 2124 | AA31: 2125 | AB31: 2126 | AC31: 2127 | AD31: 2128 | AE31: 2129 | AF31: 2130 | AG31: 2131 | AH31: 2132 | AI31: 2133 | AJ31: 2134 | AK31: 2135 | AL31: 2136 | AM31: 2137 | AN31: 2138 | AO31: 2139 | AP31: 2140 | AQ31: 2141 | AR31: 2142 | AS31: 2143 | AT31: 2144 | AU31: 2145 | AV31: 2146 | AW31: 2147 | AX31: 2148 | AY31: 2149 | AZ31: 2150 | BA31: 2151 | BB31: 2152 | BC31: 2153 | BD31: 2154 | BE31: 2155 | BF31: 2156 | BG31: 2157 | BH31: 2158 | BJ31: =B32&"st FLOOR" -> 21st FLOOR
B32: 21 | C32: {=_xlfn.XLOOKUP(C31:BH31,'[1]111W_BUILDING MATRIX'!$B$8:$B$600,'[1]111W_BUILDING MATRIX'!$E$8:$E$600,"--")} -> -- | D32: -- | E32: -- | F32: -- | G32: -- | H32: -- | I32: -- | J32: -- | K32: -- | L32: -- | M32: -- | N32: -- | O32: -- | P32: -- | Q32: -- | R32: -- | S32: -- | T32: -- | U32: -- | V32: -- | W32: -- | X32: -- | Y32: -- | Z32: -- | AA32: -- | AB32: -- | AC32: -- | AD32: -- | AE32: -- | AF32: -- | AG32: -- | AH32: -- | AI32: -- | AJ32: -- | AK32: -- | AL32: -- | AM32: -- | AN32: -- | AO32: -- | AP32: -- | AQ32: -- | AR32: -- | AS32: -- | AT32: -- | AU32: -- | AV32: -- | AW32: -- | AX32: -- | AY32: -- | AZ32: -- | BA32: -- | BB32: -- | BC32: -- | BD32: -- | BE32: -- | BF32: -- | BG32: -- | BH32: -- | BJ32: =COUNTIF(C33:BH33, "D") -> 0 | BK32: KITCHENS DELIVERED out of | BN32: =COUNTIF(C33:BH33,"<>--") -> 0 | BO32: =BJ32/BN32 -> #DIV/0!
C33: {=_xlfn.XLOOKUP(C31:BH31,'[1]111W_BUILDING MATRIX'!$B$8:$B$600,'[1]111W_BUILDING MATRIX'!$H$8:$H$600,"--")} -> -- | D33: -- | E33: -- | F33: -- | G33: -- | H33: -- | I33: -- | J33: -- | K33: -- | L33: -- | M33: -- | N33: -- | O33: -- | P33: -- | Q33: -- | R33: -- | S33: -- | T33: -- | U33: -- | V33: -- | W33: -- | X33: -- | Y33: -- | Z33: -- | AA33: -- | AB33: -- | AC33: -- | AD33: -- | AE33: -- | AF33: -- | AG33: -- | AH33: -- | AI33: -- | AJ33: -- | AK33: -- | AL33: -- | AM33: -- | AN33: -- | AO33: -- | AP33: -- | AQ33: -- | AR33: -- | AS33: -- | AT33: -- | AU33: -- | AV33: -- | AW33: -- | AX33: -- | AY33: -- | AZ33: -- | BA33: -- | BB33: -- | BC33: -- | BD33: -- | BE33: -- | BF33: -- | BG33: -- | BH33: --
C34: {=$B35*100+C$5:BH$5} -> 2001 | D34: 2002 | E34: 2003 | F34: 2004 | G34: 2005 | H34: 2006 | I34: 2007 | J34: 2008 | K34: 2009 | L34: 2010 | M34: 2011 | N34: 2012 | O34: 2013 | P34: 2014 | Q34: 2015 | R34: 2016 | S34: 2017 | T34: 2018 | U34: 2019 | V34: 2020 | W34: 2021 | X34: 2022 | Y34: 2023 | Z34: 2024 | AA34: 2025 | AB34: 2026 | AC34: 2027 | AD34: 2028 | AE34: 2029 | AF34: 2030 | AG34: 2031 | AH34: 2032 | AI34: 2033 | AJ34: 2034 | AK34: 2035 | AL34: 2036 | AM34: 2037 | AN34: 2038 | AO34: 2039 | AP34: 2040 | AQ34: 2041 | AR34: 2042 | AS34: 2043 | AT34: 2044 | AU34: 2045 | AV34: 2046 | AW34: 2047 | AX34: 2048 | AY34: 2049 | AZ34: 2050 | BA34: 2051 | BB34: 2052 | BC34: 2053 | BD34: 2054 | BE34: 2055 | BF34: 2056 | BG34: 2057 | BH34: 2058 | BJ34: =B35&"th FLOOR" -> 20th FLOOR
B35: 20 | C35: {=_xlfn.XLOOKUP(C34:BH34,'[1]111W_BUILDING MATRIX'!$B$8:$B$600,'[1]111W_BUILDING MATRIX'!$E$8:$E$600,"--")} -> -- | D35: -- | E35: -- | F35: -- | G35: -- | H35: -- | I35: -- | J35: -- | K35: -- | L35: -- | M35: -- | N35: -- | O35: -- | P35: -- | Q35: -- | R35: -- | S35: -- | T35: -- | U35: -- | V35: -- | W35: -- | X35: -- | Y35: -- | Z35: -- | AA35: -- | AB35: -- | AC35: -- | AD35: -- | AE35: -- | AF35: -- | AG35: -- | AH35: -- | AI35: -- | AJ35: -- | AK35: -- | AL35: -- | AM35: -- | AN35: -- | AO35: -- | AP35: -- | AQ35: -- | AR35: -- | AS35: -- | AT35: -- | AU35: -- | AV35: -- | AW35: -- | AX35: -- | AY35: -- | AZ35: -- | BA35: -- | BB35: -- | BC35: -- | BD35: -- | BE35: -- | BF35: -- | BG35: -- | BH35: -- | BJ35: =COUNTIF(C36:BH36, "D") -> 0 | BK35: KITCHENS DELIVERED out of | BN35: =COUNTIF(C36:BH36,"<>--") -> 0 | BO35: =BJ35/BN35 -> #DIV/0!
C36: {=_xlfn.XLOOKUP(C34:BH34,'[1]111W_BUILDING MATRIX'!$B$8:$B$600,'[1]111W_BUILDING MATRIX'!$H$8:$H$600,"--")} -> -- | D36: -- | E36: -- | F36: -- | G36: -- | H36: -- | I36: -- | J36: -- | K36: -- | L36: -- | M36: -- | N36: -- | O36: -- | P36: -- | Q36: -- | R36: -- | S36: -- | T36: -- | U36: -- | V36: -- | W36: -- | X36: -- | Y36: -- | Z36: -- | AA36: -- | AB36: -- | AC36: -- | AD36: -- | AE36: -- | AF36: -- | AG36: -- | AH36: -- | AI36: -- | AJ36: -- | AK36: -- | AL36: -- | AM36: -- | AN36: -- | AO36: -- | AP36: -- | AQ36: -- | AR36: -- | AS36: -- | AT36: -- | AU36: -- | AV36: -- | AW36: -- | AX36: -- | AY36: -- | AZ36: -- | BA36: -- | BB36: -- | BC36: -- | BD36: -- | BE36: -- | BF36: -- | BG36: -- | BH36: --
C37: {=$B38*100+C$5:BH$5} -> 1901 | D37: 1902 | E37: 1903 | F37: 1904 | G37: 1905 | H37: 1906 | I37: 1907 | J37: 1908 | K37: 1909 | L37: 1910 | M37: 1911 | N37: 1912 | O37: 1913 | P37: 1914 | Q37: 1915 | R37: 1916 | S37: 1917 | T37: 1918 | U37: 1919 | V37: 1920 | W37: 1921 | X37: 1922 | Y37: 1923 | Z37: 1924 | AA37: 1925 | AB37: 1926 | AC37: 1927 | AD37: 1928 | AE37: 1929 | AF37: 1930 | AG37: 1931 | AH37: 1932 | AI37: 1933 | AJ37: 1934 | AK37: 1935 | AL37: 1936 | AM37: 1937 | AN37: 1938 | AO37: 1939 | AP37: 1940 | AQ37: 1941 | AR37: 1942 | AS37: 1943 | AT37: 1944 | AU37: 1945 | AV37: 1946 | AW37: 1947 | AX37: 1948 | AY37: 1949 | AZ37: 1950 | BA37: 1951 | BB37: 1952 | BC37: 1953 | BD37: 1954 | BE37: 1955 | BF37: 1956 | BG37: 1957 | BH37: 1958 | BJ37: =B38&"th FLOOR" -> 19th FLOOR
B38: 19 | C38: {=_xlfn.XLOOKUP(C37:BH37,'[1]111W_BUILDING MATRIX'!$B$8:$B$600,'[1]111W_BUILDING MATRIX'!$E$8:$E$600,"--")} -> -- | D38: -- | E38: -- | F38: -- | G38: -- | H38: -- | I38: -- | J38: -- | K38: -- | L38: -- | M38: -- | N38: -- | O38: -- | P38: -- | Q38: -- | R38: -- | S38: -- | T38: -- | U38: -- | V38: -- | W38: -- | X38: -- | Y38: -- | Z38: -- | AA38: -- | AB38: -- | AC38: -- | AD38: -- | AE38: -- | AF38: -- | AG38: -- | AH38: -- | AI38: -- | AJ38: -- | AK38: -- | AL38: -- | AM38: -- | AN38: -- | AO38: -- | AP38: -- | AQ38: -- | AR38: -- | AS38: -- | AT38: -- | AU38: -- | AV38: -- | AW38: -- | AX38: -- | AY38: -- | AZ38: -- | BA38: -- | BB38: -- | BC38: -- | BD38: -- | BE38: -- | BF38: -- | BG38: -- | BH38: -- | BJ38: =COUNTIF(C39:BH39, "D") -> 0 | BK38: KITCHENS DELIVERED out of | BN38: =COUNTIF(C39:BH39,"<>--") -> 0 | BO38: =BJ38/BN38 -> #DIV/0!
C39: {=_xlfn.XLOOKUP(C37:BH37,'[1]111W_BUILDING MATRIX'!$B$8:$B$600,'[1]111W_BUILDING MATRIX'!$H$8:$H$600,"--")} -> -- | D39: -- | E39: -- | F39: -- | G39: -- | H39: -- | I39: -- | J39: -- | K39: -- | L39: -- | M39: -- | N39: -- | O39: -- | P39: -- | Q39: -- | R39: -- | S39: -- | T39: -- | U39: -- | V39: -- | W39: -- | X39: -- | Y39: -- | Z39: -- | AA39: -- | AB39: -- | AC39: -- | AD39: -- | AE39: -- | AF39: -- | AG39: -- | AH39: -- | AI39: -- | AJ39: -- | AK39: -- | AL39: -- | AM39: -- | AN39: -- | AO39: -- | AP39: -- | AQ39: -- | AR39: -- | AS39: -- | AT39: -- | AU39: -- | AV39: -- | AW39: -- | AX39: -- | AY39: -- | AZ39: -- | BA39: -- | BB39: -- | BC39: -- | BD39: -- | BE39: -- | BF39: -- | BG39: -- | BH39: --
C40: {=$B41*100+C$5:BH$5} -> 1801 | D40: 1802 | E40: 1803 | F40: 1804 | G40: 1805 | H40: 1806 | I40: 1807 | J40: 1808 | K40: 1809 | L40: 1810 | M40: 1811 | N40: 1812 | O40: 1813 | P40: 1814 | Q40: 1815 | R40: 1816 | S40: 1817 | T40: 1818 | U40: 1819 | V40: 1820 | W40: 1821 | X40: 1822 | Y40: 1823 | Z40: 1824 | AA40: 1825 | AB40: 1826 | AC40: 1827 | AD40: 1828 | AE40: 1829 | AF40: 1830 | AG40: 1831 | AH40: 1832 | AI40: 1833 | AJ40: 1834 | AK40: 1835 | AL40: 1836 | AM40: 1837 | AN40: 1838 | AO40: 1839 | AP40: 1840 | AQ40: 1841 | AR40: 1842 | AS40: 1843 | AT40: 1844 | AU40: 1845 | AV40: 1846 | AW40: 1847 | AX40: 1848 | AY40: 1849 | AZ40: 1850 | BA40: 1851 | BB40: 1852 | BC40: 1853 | BD40: 1854 | BE40: 1855 | BF40: 1856 | BG40: 1857 | BH40: 1858 | BJ40: =B41&"th FLOOR" -> 18th FLOOR
B41: 18 | C41: {=_xlfn.XLOOKUP(C40:BH40,'[1]111W_BUILDING MATRIX'!$B$8:$B$600,'[1]111W_BUILDING MATRIX'!$E$8:$E$600,"--")} -> -- | D41: -- | E41: -- | F41: -- | G41: -- | H41: -- | I41: -- | J41: -- | K41: -- | L41: -- | M41: -- | N41: -- | O41: -- | P41: -- | Q41: -- | R41: -- | S41: -- | T41: -- | U41: -- | V41: -- | W41: -- | X41: -- | Y41: -- | Z41: -- | AA41: -- | AB41: -- | AC41: -- | AD41: -- | AE41: -- | AF41: -- | AG41: -- | AH41: -- | AI41: -- | AJ41: -- | AK41: -- | AL41: -- | AM41: -- | AN41: -- | AO41: -- | AP41: -- | AQ41: -- | AR41: -- | AS41: -- | AT41: -- | AU41: -- | AV41: -- | AW41: -- | AX41: -- | AY41: -- | AZ41: -- | BA41: -- | BB41: -- | BC41: -- | BD41: -- | BE41: -- | BF41: -- | BG41: -- | BH41: -- | BJ41: =COUNTIF(C42:BH42, "D") -> 0 | BK41: KITCHENS DELIVERED out of | BN41: =COUNTIF(C42:BH42,"<>--") -> 0 | BO41: =BJ41/BN41 -> #DIV/0!
...

Sheet 111 Wall_CTNR Schedule
C2: 111 WALL-CONTAINER SCHEDULE | AL2: ="WEEK " & WEEKNUM( TODAY(), 21) -> WEEK 29
C3: FULL BREAKDOWN / SHIPPING LOGOISTICS
C5: CTNR INFORMATION | L5: LOADING SEQUENCE FR. FI | S5: SEA FREIGHT SHIPPED | W5: NY/NJ) | AA5: DELIVERY (3RD LEG) | AE5: PROJECT STATUS | AH5: PROJECT STATUS
C6: TOTAL TASKS | D6: CONT. STATUS | E6: CONT. # | F6: WEEK | G6: PICKUP WEEK | H6: FLOORS | I6: UNITS | J6: UNIT Q.ty | K6: ORDERED | L6: CONT. CODE | M6: CONT. SEAL | N6: ESTIMATED LOADING WEEK | O6: LOADED | P6: LOAD DATE | Q6: LOAD DAYS | R6: SHIPPED | S6: SHIP DATE | T6: VESSEL | U6: TRANSIT DAYS | V6: ARRIVAL | W6: ARRIVAL DATE | X6: PORT DAYS | Y6: PULLED | Z6: DELIVERED | AA6: DELIVERY DATE | AC6: TIME | AD6: LOADING AREA | AE6: ASK | AF6: CONFIRM | AG6: SENT INSTALL | AH6: ROJ | AI6: PROJECT STATUS (DELIVERED VS JOBSITE NEEDS) | AJ6: TOTAL COMMUTE | AK6: MISC NOTES | AL6: PROGRESS
C8: {='[1]111 Wall_Logistics Schedule'!$C$8:$AL$42} -> 9 | D8: PROJ | E8: 1 | F8: 32 | G8: Wk 32 | H8: 3 | I8: 301:313,315:321 | J8: 20 | K8: FALSE | L8: -- | M8: -- | N8: (08/03/26-08/09/26) | O8: FALSE | P8: 46240 | Q8: 5 | R8: FALSE | S8: 46245 | T8: -- | U8: 20 | V8: FALSE | W8: 46265 | X8: 5 | Y8: FALSE | Z8: FALSE | AA8: 46270 | AB8: Sat | AC8: -- | AD8: -- | AE8: FALSE | AF8: FALSE | AG8: FALSE | AH8: 46272 | AI8: -2 days | AJ8: -2 | AK8: 30 | AL8: -- | AP8: Date sorting Help tool
C9: 9 | D9: PROJ | E9: 2 | F9: 32 | G9: Wk 32 | H9: 3 | I9: 322:333,335:342 | J9: 20 | K9: FALSE | L9: -- | M9: -- | N9: (08/03/26-08/09/26) | O9: FALSE | P9: 46240 | Q9: 5 | R9: FALSE | S9: 46245 | T9: -- | U9: 20 | V9: FALSE | W9: 46265 | X9: 5 | Y9: FALSE | Z9: FALSE | AA9: 46270 | AB9: Sat | AC9: -- | AD9: -- | AE9: FALSE | AF9: FALSE | AG9: FALSE | AH9: 46272 | AI9: -2 days | AJ9: -2 | AK9: 30 | AL9: -- | AP9: {=_xlfn.LET(_xlpm.rng,$C$8:$AL$45,_xlpm.d,$AA$8:$AA$45,_xlpm.mask,(ISNUMBER(_xlpm.d))*(_xlpm.d>=TODAY()),_xlpm.rows_upcoming,_xlfn._xlws.FILTER(_xlpm.rng,_xlpm.mask),_xlpm.d_upcoming,_xlfn._xlws.FILTER(_xlpm.d,_xlpm.mask),_xlpm.sorted,_xlfn.SORTBY(_xlpm.rows_upcoming,_xlpm.d_upcoming,1,_xlfn._xlws.FILTER($E$8:$E$45,_xlpm.mask),1),_xlfn.TAKE(_xlpm.sorted,33))} -> 9 | AQ9: PROJ | AR9: 1 | AS9: 32 | AT9: Wk 32 | AU9: 3 | AV9: 301:313,315:321 | AW9: 20 | AX9: FALSE | AY9: -- | AZ9: -- | BA9: (08/03/26-08/09/26) | BB9: FALSE | BC9: 46240 | BD9: 5 | BE9: FALSE | BF9: 46245 | BG9: -- | BH9: 20 | BI9: FALSE | BJ9: 46265 | BK9: 5 | BL9: FALSE | BM9: FALSE | BN9: 46270 | BO9: Sat | BP9: -- | BQ9: -- | BR9: FALSE | BS9: FALSE | BT9: FALSE | BU9: 46272 | BV9: -2 days | BW9: -2 | BX9: 30 | BY9: --
C10: 9 | D10: PROJ | E10: 3 | F10: 32 | G10: Wk 32 | H10: 3,4 | I10: 343:349,352:354,356:358,401:407 | J10: 20 | K10: FALSE | L10: -- | M10: -- | N10: (08/03/26-08/09/26) | O10: FALSE | P10: 46240 | Q10: 5 | R10: FALSE | S10: 46245 | T10: -- | U10: 20 | V10: FALSE | W10: 46265 | X10: 5 | Y10: FALSE | Z10: FALSE | AA10: 46270 | AB10: Sat | AC10: -- | AD10: -- | AE10: FALSE | AF10: FALSE | AG10: FALSE | AH10: 46272 | AI10: -2 days | AJ10: -2 | AK10: 30 | AL10: -- | AP10: 9 | AQ10: PROJ | AR10: 2 | AS10: 32 | AT10: Wk 32 | AU10: 3 | AV10: 322:333,335:342 | AW10: 20 | AX10: FALSE | AY10: -- | AZ10: -- | BA10: (08/03/26-08/09/26) | BB10: FALSE | BC10: 46240 | BD10: 5 | BE10: FALSE | BF10: 46245 | BG10: -- | BH10: 20 | BI10: FALSE | BJ10: 46265 | BK10: 5 | BL10: FALSE | BM10: FALSE | BN10: 46270 | BO10: Sat | BP10: -- | BQ10: -- | BR10: FALSE | BS10: FALSE | BT10: FALSE | BU10: 46272 | BV10: -2 days | BW10: -2 | BX10: 30 | BY10: --
C11: 9 | D11: PROJ | E11: 4 | F11: 37 | G11: Wk 37 | H11: 4 | I11: 408:425 | J11: 18 | K11: FALSE | L11: -- | M11: -- | N11: (09/07/26-09/13/26) | O11: FALSE | P11: 46275 | Q11: 5 | R11: FALSE | S11: 46280 | T11: -- | U11: 20 | V11: FALSE | W11: 46300 | X11: 5 | Y11: FALSE | Z11: FALSE | AA11: 46305 | AB11: Sat | AC11: -- | AD11: -- | AE11: FALSE | AF11: FALSE | AG11: FALSE | AH11: 46300 | AI11: +5 days | AJ11: 5 | AK11: 30 | AL11: -- | AP11: 9 | AQ11: PROJ | AR11: 3 | AS11: 32 | AT11: Wk 32 | AU11: 3,4 | AV11: 343:349,352:354,356:358,401:407 | AW11: 20 | AX11: FALSE | AY11: -- | AZ11: -- | BA11: (08/03/26-08/09/26) | BB11: FALSE | BC11: 46240 | BD11: 5 | BE11: FALSE | BF11: 46245 | BG11: -- | BH11: 20 | BI11: FALSE | BJ11: 46265 | BK11: 5 | BL11: FALSE | BM11: FALSE | BN11: 46270 | BO11: Sat | BP11: -- | BQ11: -- | BR11: FALSE | BS11: FALSE | BT11: FALSE | BU11: 46272 | BV11: -2 days | BW11: -2 | BX11: 30 | BY11: --
C12: 9 | D12: PROJ | E12: 5 | F12: 37 | G12: Wk 37 | H12: 4 | I12: 426:443 | J12: 18 | K12: FALSE | L12: -- | M12: -- | N12: (09/07/26-09/13/26) | O12: FALSE | P12: 46275 | Q12: 5 | R12: FALSE | S12: 46280 | T12: -- | U12: 20 | V12: FALSE | W12: 46300 | X12: 5 | Y12: FALSE | Z12: FALSE | AA12: 46305 | AB12: Sat | AC12: -- | AD12: -- | AE12: FALSE | AF12: FALSE | AG12: FALSE | AH12: 46300 | AI12: +5 days | AJ12: 5 | AK12: 30 | AL12: -- | AP12: 9 | AQ12: PROJ | AR12: 4 | AS12: 37 | AT12: Wk 37 | AU12: 4 | AV12: 408:425 | AW12: 18 | AX12: FALSE | AY12: -- | AZ12: -- | BA12: (09/07/26-09/13/26) | BB12: FALSE | BC12: 46275 | BD12: 5 | BE12: FALSE | BF12: 46280 | BG12: -- | BH12: 20 | BI12: FALSE | BJ12: 46300 | BK12: 5 | BL12: FALSE | BM12: FALSE | BN12: 46305 | BO12: Sat | BP12: -- | BQ12: -- | BR12: FALSE | BS12: FALSE | BT12: FALSE | BU12: 46300 | BV12: +5 days | BW12: 5 | BX12: 30 | BY12: --
C13: 9 | D13: PROJ | E13: 6 | F13: 38 | G13: Wk 38 | H13: 4,5 | I13: 444:449,452:458,501:503 | J13: 16 | K13: FALSE | L13: -- | M13: -- | N13: (09/14/26-09/20/26) | O13: FALSE | P13: 46282 | Q13: 5 | R13: FALSE | S13: 46287 | T13: -- | U13: 20 | V13: FALSE | W13: 46307 | X13: 5 | Y13: FALSE | Z13: FALSE | AA13: 46312 | AB13: Sat | AC13: -- | AD13: -- | AE13: FALSE | AF13: FALSE | AG13: FALSE | AH13: 46300 | AI13: +12 days | AJ13: 12 | AK13: 30 | AL13: -- | AP13: 9 | AQ13: PROJ | AR13: 5 | AS13: 37 | AT13: Wk 37 | AU13: 4 | AV13: 426:443 | AW13: 18 | AX13: FALSE | AY13: -- | AZ13: -- | BA13: (09/07/26-09/13/26) | BB13: FALSE | BC13: 46275 | BD13: 5 | BE13: FALSE | BF13: 46280 | BG13: -- | BH13: 20 | BI13: FALSE | BJ13: 46300 | BK13: 5 | BL13: FALSE | BM13: FALSE | BN13: 46305 | BO13: Sat | BP13: -- | BQ13: -- | BR13: FALSE | BS13: FALSE | BT13: FALSE | BU13: 46300 | BV13: +5 days | BW13: 5 | BX13: 30 | BY13: --
C14: 9 | D14: PROJ | E14: 7 | F14: 38 | G14: Wk 38 | H14: 5 | I14: 504:521 | J14: 18 | K14: FALSE | L14: -- | M14: -- | N14: (09/14/26-09/20/26) | O14: FALSE | P14: 46282 | Q14: 5 | R14: FALSE | S14: 46287 | T14: -- | U14: 20 | V14: FALSE | W14: 46307 | X14: 5 | Y14: FALSE | Z14: FALSE | AA14: 46312 | AB14: Sat | AC14: -- | AD14: -- | AE14: FALSE | AF14: FALSE | AG14: FALSE | AH14: 46314 | AI14: -2 days | AJ14: -2 | AK14: 30 | AL14: -- | AP14: 9 | AQ14: PROJ | AR14: 6 | AS14: 38 | AT14: Wk 38 | AU14: 4,5 | AV14: 444:449,452:458,501:503 | AW14: 16 | AX14: FALSE | AY14: -- | AZ14: -- | BA14: (09/14/26-09/20/26) | BB14: FALSE | BC14: 46282 | BD14: 5 | BE14: FALSE | BF14: 46287 | BG14: -- | BH14: 20 | BI14: FALSE | BJ14: 46307 | BK14: 5 | BL14: FALSE | BM14: FALSE | BN14: 46312 | BO14: Sat | BP14: -- | BQ14: -- | BR14: FALSE | BS14: FALSE | BT14: FALSE | BU14: 46300 | BV14: +12 days | BW14: 12 | BX14: 30 | BY14: --
C15: 9 | D15: PROJ | E15: 8 | F15: 39 | G15: Wk 39 | H15: 5 | I15: 522:539 | J15: 18 | K15: FALSE | L15: -- | M15: -- | N15: (09/21/26-09/27/26) | O15: FALSE | P15: 46289 | Q15: 5 | R15: FALSE | S15: 46294 | T15: -- | U15: 20 | V15: FALSE | W15: 46314 | X15: 5 | Y15: FALSE | Z15: FALSE | AA15: 46319 | AB15: Sat | AC15: -- | AD15: -- | AE15: FALSE | AF15: FALSE | AG15: FALSE | AH15: 46314 | AI15: +5 days | AJ15: 5 | AK15: 30 | AL15: -- | AP15: 9 | AQ15: PROJ | AR15: 7 | AS15: 38 | AT15: Wk 38 | AU15: 5 | AV15: 504:521 | AW15: 18 | AX15: FALSE | AY15: -- | AZ15: -- | BA15: (09/14/26-09/20/26) | BB15: FALSE | BC15: 46282 | BD15: 5 | BE15: FALSE | BF15: 46287 | BG15: -- | BH15: 20 | BI15: FALSE | BJ15: 46307 | BK15: 5 | BL15: FALSE | BM15: FALSE | BN15: 46312 | BO15: Sat | BP15: -- | BQ15: -- | BR15: FALSE | BS15: FALSE | BT15: FALSE | BU15: 46314 | BV15: -2 days | BW15: -2 | BX15: 30 | BY15: --
C16: 9 | D16: PROJ | E16: 9 | F16: 39 | G16: Wk 39 | H16: 5 | I16: 540:549,552:557 | J16: 16 | K16: FALSE | L16: -- | M16: -- | N16: (09/21/26-09/27/26) | O16: FALSE | P16: 46289 | Q16: 5 | R16: FALSE | S16: 46294 | T16: -- | U16: 20 | V16: FALSE | W16: 46314 | X16: 5 | Y16: FALSE | Z16: FALSE | AA16: 46319 | AB16: Sat | AC16: -- | AD16: -- | AE16: FALSE | AF16: FALSE | AG16: FALSE | AH16: 46314 | AI16: +5 days | AJ16: 5 | AK16: 30 | AL16: -- | AP16: 9 | AQ16: PROJ | AR16: 8 | AS16: 39 | AT16: Wk 39 | AU16: 5 | AV16: 522:539 | AW16: 18 | AX16: FALSE | AY16: -- | AZ16: -- | BA16: (09/21/26-09/27/26) | BB16: FALSE | BC16: 46289 | BD16: 5 | BE16: FALSE | BF16: 46294 | BG16: -- | BH16: 20 | BI16: FALSE | BJ16: 46314 | BK16: 5 | BL16: FALSE | BM16: FALSE | BN16: 46319 | BO16: Sat | BP16: -- | BQ16: -- | BR16: FALSE | BS16: FALSE | BT16: FALSE | BU16: 46314 | BV16: +5 days | BW16: 5 | BX16: 30 | BY16: --
C17: 9 | D17: PROJ | E17: 10 | F17: 40 | G17: Wk 40 | H17: 5,6 | I17: 558,601:617 | J17: 18 | K17: FALSE | L17: -- | M17: -- | N17: (09/28/26-10/04/26) | O17: FALSE | P17: 46296 | Q17: 5 | R17: FALSE | S17: 46301 | T17: -- | U17: 20 | V17: FALSE | W17: 46321 | X17: 5 | Y17: FALSE | Z17: FALSE | AA17: 46326 | AB17: Sat | AC17: -- | AD17: -- | AE17: FALSE | AF17: FALSE | AG17: FALSE | AH17: 46314 | AI17: +12 days | AJ17: 12 | AK17: 30 | AL17: -- | AP17: 9 | AQ17: PROJ | AR17: 9 | AS17: 39 | AT17: Wk 39 | AU17: 5 | AV17: 540:549,552:557 | AW17: 16 | AX17: FALSE | AY17: -- | AZ17: -- | BA17: (09/21/26-09/27/26) | BB17: FALSE | BC17: 46289 | BD17: 5 | BE17: FALSE | BF17: 46294 | BG17: -- | BH17: 20 | BI17: FALSE | BJ17: 46314 | BK17: 5 | BL17: FALSE | BM17: FALSE | BN17: 46319 | BO17: Sat | BP17: -- | BQ17: -- | BR17: FALSE | BS17: FALSE | BT17: FALSE | BU17: 46314 | BV17: +5 days | BW17: 5 | BX17: 30 | BY17: --
C18: 9 | D18: PROJ | E18: 11 | F18: 40 | G18: Wk 40 | H18: 6 | I18: 618:635 | J18: 18 | K18: FALSE | L18: -- | M18: -- | N18: (09/28/26-10/04/26) | O18: FALSE | P18: 46296 | Q18: 5 | R18: FALSE | S18: 46301 | T18: -- | U18: 20 | V18: FALSE | W18: 46321 | X18: 5 | Y18: FALSE | Z18: FALSE | AA18: 46326 | AB18: Sat | AC18: -- | AD18: -- | AE18: FALSE | AF18: FALSE | AG18: FALSE | AH18: 46328 | AI18: -2 days | AJ18: -2 | AK18: 30 | AL18: -- | AP18: 9 | AQ18: PROJ | AR18: 10 | AS18: 40 | AT18: Wk 40 | AU18: 5,6 | AV18: 558,601:617 | AW18: 18 | AX18: FALSE | AY18: -- | AZ18: -- | BA18: (09/28/26-10/04/26) | BB18: FALSE | BC18: 46296 | BD18: 5 | BE18: FALSE | BF18: 46301 | BG18: -- | BH18: 20 | BI18: FALSE | BJ18: 46321 | BK18: 5 | BL18: FALSE | BM18: FALSE | BN18: 46326 | BO18: Sat | BP18: -- | BQ18: -- | BR18: FALSE | BS18: FALSE | BT18: FALSE | BU18: 46314 | BV18: +12 days | BW18: 12 | BX18: 30 | BY18: --
C19: 9 | D19: PROJ | E19: 12 | F19: 41 | G19: Wk 41 | H19: 6 | I19: 636:649,652:653 | J19: 16 | K19: FALSE | L19: -- | M19: -- | N19: (10/05/26-10/11/26) | O19: FALSE | P19: 46303 | Q19: 5 | R19: FALSE | S19: 46308 | T19: -- | U19: 20 | V19: FALSE | W19: 46328 | X19: 5 | Y19: FALSE | Z19: FALSE | AA19: 46333 | AB19: Sat | AC19: -- | AD19: -- | AE19: FALSE | AF19: FALSE | AG19: FALSE | AH19: 46328 | AI19: +5 days | AJ19: 5 | AK19: 30 | AL19: -- | AP19: 9 | AQ19: PROJ | AR19: 11 | AS19: 40 | AT19: Wk 40 | AU19: 6 | AV19: 618:635 | AW19: 18 | AX19: FALSE | AY19: -- | AZ19: -- | BA19: (09/28/26-10/04/26) | BB19: FALSE | BC19: 46296 | BD19: 5 | BE19: FALSE | BF19: 46301 | BG19: -- | BH19: 20 | BI19: FALSE | BJ19: 46321 | BK19: 5 | BL19: FALSE | BM19: FALSE | BN19: 46326 | BO19: Sat | BP19: -- | BQ19: -- | BR19: FALSE | BS19: FALSE | BT19: FALSE | BU19: 46328 | BV19: -2 days | BW19: -2 | BX19: 30 | BY19: --
C20: 9 | D20: PROJ | E20: 13 | F20: 41 | G20: Wk 41 | H20: 6,7 | I20: 654:658,701:713 | J20: 18 | K20: FALSE | L20: -- | M20: -- | N20: (10/05/26-10/11/26) | O20: FALSE | P20: 46303 | Q20: 5 | R20: FALSE | S20: 46308 | T20: -- | U20: 20 | V20: FALSE | W20: 46328 | X20: 5 | Y20: FALSE | Z20: FALSE | AA20: 46333 | AB20: Sat | AC20: -- | AD20: -- | AE20: FALSE | AF20: FALSE | AG20: FALSE | AH20: 46328 | AI20: +5 days | AJ20: 5 | AK20: 30 | AL20: -- | AP20: 9 | AQ20: PROJ | AR20: 12 | AS20: 41 | AT20: Wk 41 | AU20: 6 | AV20: 636:649,652:653 | AW20: 16 | AX20: FALSE | AY20: -- | AZ20: -- | BA20: (10/05/26-10/11/26) | BB20: FALSE | BC20: 46303 | BD20: 5 | BE20: FALSE | BF20: 46308 | BG20: -- | BH20: 20 | BI20: FALSE | BJ20: 46328 | BK20: 5 | BL20: FALSE | BM20: FALSE | BN20: 46333 | BO20: Sat | BP20: -- | BQ20: -- | BR20: FALSE | BS20: FALSE | BT20: FALSE | BU20: 46328 | BV20: +5 days | BW20: 5 | BX20: 30 | BY20: --
C21: 9 | D21: PROJ | E21: 14 | F21: 42 | G21: Wk 42 | H21: 7 | I21: 714:731 | J21: 18 | K21: FALSE | L21: -- | M21: -- | N21: (10/12/26-10/18/26) | O21: FALSE | P21: 46310 | Q21: 5 | R21: FALSE | S21: 46315 | T21: -- | U21: 20 | V21: FALSE | W21: 46335 | X21: 5 | Y21: FALSE | Z21: FALSE | AA21: 46340 | AB21: Sat | AC21: -- | AD21: -- | AE21: FALSE | AF21: FALSE | AG21: FALSE | AH21: 46342 | AI21: -2 days | AJ21: -2 | AK21: 30 | AL21: -- | AP21: 9 | AQ21: PROJ | AR21: 13 | AS21: 41 | AT21: Wk 41 | AU21: 6,7 | AV21: 654:658,701:713 | AW21: 18 | AX21: FALSE | AY21: -- | AZ21: -- | BA21: (10/05/26-10/11/26) | BB21: FALSE | BC21: 46303 | BD21: 5 | BE21: FALSE | BF21: 46308 | BG21: -- | BH21: 20 | BI21: FALSE | BJ21: 46328 | BK21: 5 | BL21: FALSE | BM21: FALSE | BN21: 46333 | BO21: Sat | BP21: -- | BQ21: -- | BR21: FALSE | BS21: FALSE | BT21: FALSE | BU21: 46328 | BV21: +5 days | BW21: 5 | BX21: 30 | BY21: --
... C38: 9 | D38: PROJ | E38: 31 | F38: 51 | G38: Wk 51 | H38: 12 | I38: 1230:1247 | J38: 18 | K38: FALSE | L38: -- | M38: -- | N38: (12/14/26-12/20/26) | O38: FALSE | P38: 46373 | Q38: 5 | R38: FALSE | S38: 46378 | T38: -- | U38: 20 | V38: FALSE | W38: 46398 | X38: 5 | Y38: FALSE | Z38: FALSE | AA38: 46403 | AB38: Sat | AC38: -- | AD38: -- | AE38: FALSE | AF38: FALSE | AG38: FALSE | AH38: 46412 | AI38: -9 days | AJ38: -9 | AK38: 30 | AL38: -- | AP38: 9 | AQ38: PROJ | AR38: 30 | AS38: 51 | AT38: Wk 51 | AU38: 12 | AV38: 1212:1229 | AW38: 18 | AX38: FALSE | AY38: -- | AZ38: -- | BA38: (12/14/26-12/20/26) | BB38: FALSE | BC38: 46373 | BD38: 5 | BE38: FALSE | BF38: 46378 | BG38: -- | BH38: 20 | BI38: FALSE | BJ38: 46398 | BK38: 5 | BL38: FALSE | BM38: FALSE | BN38: 46403 | BO38: Sat | BP38: -- | BQ38: -- | BR38: FALSE | BS38: FALSE | BT38: FALSE | BU38: 46412 | BV38: -9 days | BW38: -9 | BX38: 30 | BY38: HOIST
C39: 9 | D39: PROJ | E39: Doors | F39: 54 | G39: Wk 54 | H39: 3 | I39: 3rd Floor Doors | J39: 58 | K39: FALSE | L39: -- | M39: -- | N39: (01/04/27-01/10/27) | O39: FALSE | P39: 46394 | Q39: 5 | R39: FALSE | S39: 46399 | T39: -- | U39: 20 | V39: FALSE | W39: 46419 | X39: 5 | Y39: FALSE | Z39: FALSE | AA39: 46424 | AB39: Sat | AC39: -- | AD39: -- | AE39: FALSE | AF39: FALSE | AG39: FALSE | AH39: unknown | AK39: 30 | AL39: -- | AP39: 9 | AQ39: PROJ | AR39: 31 | AS39: 51 | AT39: Wk 51 | AU39: 12 | AV39: 1230:1247 | AW39: 18 | AX39: FALSE | AY39: -- | AZ39: -- | BA39: (12/14/26-12/20/26) | BB39: FALSE | BC39: 46373 | BD39: 5 | BE39: FALSE | BF39: 46378 | BG39: -- | BH39: 20 | BI39: FALSE | BJ39: 46398 | BK39: 5 | BL39: FALSE | BM39: FALSE | BN39: 46403 | BO39: Sat | BP39: -- | BQ39: -- | BR39: FALSE | BS39: FALSE | BT39: FALSE | BU39: 46412 | BV39: -9 days | BW39: -9 | BX39: 30 | BY39: --
C40: 9 | D40: PROJ | E40: H1 | F40: 51 | G40: Wk 51 | H40: 3:10 | I40: 350:351,450:451,550:551,650:651,750:751,850:851,950:951,1050:1051 | J40: 16 | K40: FALSE | L40: -- | M40: -- | N40: (12/14/26-12/20/26) | O40: FALSE | P40: 46373 | Q40: 5 | R40: FALSE | S40: 46378 | T40: -- | U40: 20 | V40: FALSE | W40: 46398 | X40: 5 | Y40: FALSE | Z40: FALSE | AA40: 46403 | AB40: 0 | AC40: -- | AD40: -- | AE40: FALSE | AF40: FALSE | AG40: FALSE | AH40: 46384 | AI40: +19 days | AJ40: 19 | AK40: 30 | AL40: -- | AP40: 9 | AQ40: PROJ | AR40: H1 | AS40: 51 | AT40: Wk 51 | AU40: 3:10 | AV40: 350:351,450:451,550:551,650:651,750:751,850:851,950:951,1050:1051 | AW40: 16 | AX40: FALSE | AY40: -- | AZ40: -- | BA40: (12/14/26-12/20/26) | BB40: FALSE | BC40: 46373 | BD40: 5 | BE40: FALSE | BF40: 46378 | BG40: -- | BH40: 20 | BI40: FALSE | BJ40: 46398 | BK40: 5 | BL40: FALSE | BM40: FALSE | BN40: 46403 | BO40: 0 | BP40: -- | BQ40: -- | BR40: FALSE | BS40: FALSE | BT40: FALSE | BU40: 46384 | BV40: +19 days | BW40: 19 | BX40: 30 | BY40: --
C41: 0 | D41: 0 | E41: 0 | F41: 0 | G41: 0 | H41: 0 | I41: 0 | J41: 0 | K41: 0 | L41: 0 | M41: 0 | N41: 0 | O41: 0 | P41: 0 | Q41: 0 | R41: 0 | S41: 0 | T41: 0 | U41: 0 | V41: 0 | W41: 0 | X41: 0 | Y41: 0 | Z41: 0 | AA41: 0 | AB41: 0 | AC41: 0 | AD41: 0 | AE41: 0 | AF41: 0 | AG41: 0 | AH41: 0 | AI41: 0 | AJ41: 0 | AK41: 0 | AL41: 0 | AP41: 9 | AQ41: PROJ | AR41: Doors | AS41: 54 | AT41: Wk 54 | AU41: 3 | AV41: 3rd Floor Doors | AW41: 58 | AX41: FALSE | AY41: -- | AZ41: -- | BA41: (01/04/27-01/10/27) | BB41: FALSE | BC41: 46394 | BD41: 5 | BE41: FALSE | BF41: 46399 | BG41: -- | BH41: 20 | BI41: FALSE | BJ41: 46419 | BK41: 5 | BL41: FALSE | BM41: FALSE | BN41: 46424 | BO41: Sat | BP41: -- | BQ41: -- | BR41: FALSE | BS41: FALSE | BT41: FALSE | BU41: unknown | BX41: 30 | BY41: --
C42: 0 | D42: 0 | E42: 0 | F42: 0 | G42: 0 | H42: 0 | I42: 0 | J42: 0 | K42: 0 | L42: 0 | M42: 0 | N42: 0 | O42: 0 | P42: 0 | Q42: 0 | R42: 0 | S42: 0 | T42: 0 | U42: 0 | V42: 0 | W42: 0 | X42: 0 | Y42: 0 | Z42: 0 | AA42: 0 | AB42: 0 | AC42: 0 | AD42: 0 | AE42: 0 | AF42: 0 | AG42: 0 | AH42: 0 | AI42: 0 | AJ42: 0 | AK42: 0 | AL42: 0

Sheet 111 Wall to CCM
B2: #VALUE! | C2: 111 Wall - Concerto Millwork - Scheduling | N2: =TODAY() -> 46217
C3: Apartment Tower - 58 units x X floors | O3: ="WEEK " &WEEKNUM(TODAY()) -> WEEK 29
B6: Total Containers | D6: Units Delivered | H6: Container Status | L6: Damages
B7: =COUNTIF('111 Wall_CTNR Schedule'!E8:E45,"<>") -> 35 | D7: =SUMIF('111 Wall_CTNR Schedule'!D8:D45,"D", '111 Wall_CTNR Schedule'!J8:J45) -> 0 | H7: PROJECTED | I7: {=SUMPRODUCT(--('111 Wall_CTNR Schedule'!D$8:D$45="PROJ"))} -> 33 | J7: =SUM(I7)/SUM($I$7:$I$12) -> 1 | L7: TBD
B8: TCO 1 + Only | D8: ="Of "&SUM('111 Wall_CTNR Schedule'!J8:J45) & " Units" -> Of 622 Units | H8: LOADING | I8: {=SUMPRODUCT(--('111 Wall_CTNR Schedule'!D$8:D$45="LDG"))} -> 0 | J8: =SUM(I8)/SUM($I$7:$I$12) -> 0
H9: LOADED | I9: {=SUMPRODUCT(--('111 Wall_CTNR Schedule'!D$8:D$45="LDD"))} -> 0 | J9: =SUM(I9)/SUM($I$7:$I$12) -> 0
H10: ENROUTE | I10: {=SUMPRODUCT(--('111 Wall_CTNR Schedule'!D$8:D$45="ENR"))} -> 0 | J10: =SUM(I10)/SUM($I$7:$I$12) -> 0
B11: Transit Performance | H11: IN PORT | I11: {=SUMPRODUCT(--('111 Wall_CTNR Schedule'!D$8:D$45="INPRT"))} -> 0 | J11: =SUM(I11)/SUM($I$7:$I$12) -> 0
B12: Average Load Days | D12: =AVERAGE('111 Wall_CTNR Schedule'!Q8:Q45) -> 4.7142857 | H12: DELIVERED | I12: {=SUMPRODUCT(--('111 Wall_CTNR Schedule'!D$8:D$45="D"))} -> 0 | J12: =SUM(I12)/SUM($I$7:$I$12) -> 0
B13: Average Sea Transit Days | D13: =AVERAGE('111 Wall_CTNR Schedule'!U8:U45) -> 18.857143
B14: Average In Port Days | D14: =AVERAGE('111 Wall_CTNR Schedule'!X8:X45) -> 4.7142857
B15: Total Transit Time | D15: =SUM(D12:D14) -> 28.285714
B19: Container Schedule
B20: CTNR No. | C20: Status | D20: CTNR Code | E20: Load WK | F20: Load Date | G20: ETA NY | H20: DELIVERY | I20: Confirmed? | J20: Floor | K20: Unit Q.ty | M20: Units
B21: NEXT UP
B22: {=IF('111 Wall_CTNR Schedule'!E8:E40=0," ","CTN " & '111 Wall_CTNR Schedule'!E8:E40)} -> CTN 1 | C22: {=IF('111 Wall_CTNR Schedule'!D8:D40=0," ",'111 Wall_CTNR Schedule'!D8:D40)} -> PROJ | D22: {=IF('111 Wall_CTNR Schedule'!L8:L40=0," ",'111 Wall_CTNR Schedule'!L8:L40)} -> -- | E22: {=IF('111 Wall_CTNR Schedule'!F8:F45=0," ","Wk " &'111 Wall_CTNR Schedule'!F8:F45)} -> Wk 32 | F22: {=IF('111 Wall_CTNR Schedule'!P8:P45=0," ",TEXT('111 Wall_CTNR Schedule'!P8:P45, "mmm-dd"))} -> Aug-06 | G22: {=IF('111 Wall_CTNR Schedule'!W8:W45=0," ",TEXT('111 Wall_CTNR Schedule'!W8:W45,"mmm-dd"))} -> Aug-31 | H22: {=IF('111 Wall_CTNR Schedule'!AA8:AA45=0," ",TEXT('111 Wall_CTNR Schedule'!AA8:AA45,"ddd mmm dd"))} -> Sat Sep 05 | I22: {=IF('111 Wall_CTNR Schedule'!E8:E45=0," ",IF('111 Wall_CTNR Schedule'!AF8:AF45=TRUE,"Confirmed","ETA"))} -> ETA | J22: {=IF('111 Wall_CTNR Schedule'!H8:H45=0," ","FL " & '111 Wall_CTNR Schedule'!H8:H45)} -> FL 3 | K22: {=IF('111 Wall_CTNR Schedule'!J8:J45=0," ",'111 Wall_CTNR Schedule'!J8:J45& "x")} -> 20x | M22: {=IF('111 Wall_CTNR Schedule'!I8:I45=0," ",'111 Wall_CTNR Schedule'!I8:I45)} -> 301:313,315:321
B23: CTN 2 | C23: PROJ | D23: -- | E23: Wk 32 | F23: Aug-06 | G23: Aug-31 | H23: Sat Sep 05 | I23: ETA | J23: FL 3 | K23: 20x | M23: 322:333,335:342
B24: CTN 3 | C24: PROJ | D24: -- | E24: Wk 32 | F24: Aug-06 | G24: Aug-31 | H24: Sat Sep 05 | I24: ETA | J24: FL 3,4 | K24: 20x | M24: 343:349,352:354,356:358,401:407
B25: CTN 4 | C25: PROJ | D25: -- | E25: Wk 37 | F25: Sep-10 | G25: Oct-05 | H25: Sat Oct 10 | I25: ETA | J25: FL 4 | K25: 18x | M25: 408:425
B26: CTN 5 | C26: PROJ | D26: -- | E26: Wk 37 | F26: Sep-10 | G26: Oct-05 | H26: Sat Oct 10 | I26: ETA | J26: FL 4 | K26: 18x | M26: 426:443
B27: CTN 6 | C27: PROJ | D27: -- | E27: Wk 38 | F27: Sep-17 | G27: Oct-12 | H27: Sat Oct 17 | I27: ETA | J27: FL 4,5 | K27: 16x | M27: 444:449,452:458,501:503
B28: CTN 7 | C28: PROJ | D28: -- | E28: Wk 38 | F28: Sep-17 | G28: Oct-12 | H28: Sat Oct 17 | I28: ETA | J28: FL 5 | K28: 18x | M28: 504:521
B29: CTN 8 | C29: PROJ | D29: -- | E29: Wk 39 | F29: Sep-24 | G29: Oct-19 | H29: Sat Oct 24 | I29: ETA | J29: FL 5 | K29: 18x | M29: 522:539
B30: CTN 9 | C30: PROJ | D30: -- | E30: Wk 39 | F30: Sep-24 | G30: Oct-19 | H30: Sat Oct 24 | I30: ETA | J30: FL 5 | K30: 16x | M30: 540:549,552:557
B31: CTN 10 | C31: PROJ | D31: -- | E31: Wk 40 | F31: Oct-01 | G31: Oct-26 | H31: Sat Oct 31 | I31: ETA | J31: FL 5,6 | K31: 18x | M31: 558,601:617
B32: CTN 11 | C32: PROJ | D32: -- | E32: Wk 40 | F32: Oct-01 | G32: Oct-26 | H32: Sat Oct 31 | I32: ETA | J32: FL 6 | K32: 18x | M32: 618:635
B33: CTN 12 | C33: PROJ | D33: -- | E33: Wk 41 | F33: Oct-08 | G33: Nov-02 | H33: Sat Nov 07 | I33: ETA | J33: FL 6 | K33: 16x | M33: 636:649,652:653
B34: CTN 13 | C34: PROJ | D34: -- | E34: Wk 41 | F34: Oct-08 | G34: Nov-02 | H34: Sat Nov 07 | I34: ETA | J34: FL 6,7 | K34: 18x | M34: 654:658,701:713
... B54: CTN H1 | C54: PROJ | D54: -- | E54: Wk 51 | F54: Dec-17 | G54: Jan-11 | H54: Sat Jan 16 | I54: ETA | J54: FL 3:10 | K54: 16x | M54: 350:351,450:451,550:551,650:651,750:751,850:851,950:951,1050:1051

Sheet CTNR-Floor
B3: 111 WALL CTNR/FLOOR
B5: TCO# | C5: Floor # | D5: ROJ Date | E5: CTNRs
B6: TCO#1 | C6: {=ROW(3:29)} -> 3 | D6: {='[1]ROJ Dates'!$D$6:$D$32} -> 46272 | E6: {=IFERROR("CTN " & INDEX('111 Wall_CTNR Schedule'!$E$8:$E$40,SMALL(IF(LEFT(SUBSTITUTE('111 Wall_CTNR Schedule'!$H$8:$H$40," ","")&",",LEN($C6&"")+1)=$C6&",",ROW('111 Wall_CTNR Schedule'!$H$8:$H$40)-ROW('111 Wall_CTNR Schedule'!$H$8)+1),COLUMNS($D6:D6))),"")} -> CTN 1 | F6: {=IFERROR("CTN " & INDEX('111 Wall_CTNR Schedule'!$E$8:$E$40,SMALL(IF(LEFT(SUBSTITUTE('111 Wall_CTNR Schedule'!$H$8:$H$40," ","")&",",LEN($C6&"")+1)=$C6&",",ROW('111 Wall_CTNR Schedule'!$H$8:$H$40)-ROW('111 Wall_CTNR Schedule'!$H$8)+1),COLUMNS($D6:E6))),"")} -> CTN 2 | G6: {=IFERROR("CTN " & INDEX('111 Wall_CTNR Schedule'!$E$8:$E$40,SMALL(IF(LEFT(SUBSTITUTE('111 Wall_CTNR Schedule'!$H$8:$H$40," ","")&",",LEN($C6&"")+1)=$C6&",",ROW('111 Wall_CTNR Schedule'!$H$8:$H$40)-ROW('111 Wall_CTNR Schedule'!$H$8)+1),COLUMNS($D6:F6))),"")} -> CTN 3 | H6: {=IFERROR("CTN " & INDEX('111 Wall_CTNR Schedule'!$E$8:$E$40,SMALL(IF(LEFT(SUBSTITUTE('111 Wall_CTNR Schedule'!$H$8:$H$40," ","")&",",LEN($C6&"")+1)=$C6&",",ROW('111 Wall_CTNR Schedule'!$H$8:$H$40)-ROW('111 Wall_CTNR Schedule'!$H$8)+1),COLUMNS($D6:G6))),"")} -> CTN Doors | I6: {=IFERROR("CTN " & INDEX('111 Wall_CTNR Schedule'!$E$8:$E$40,SMALL(IF(LEFT(SUBSTITUTE('111 Wall_CTNR Schedule'!$H$8:$H$40," ","")&",",LEN($C6&"")+1)=$C6&",",ROW('111 Wall_CTNR Schedule'!$H$8:$H$40)-ROW('111 Wall_CTNR Schedule'!$H$8)+1),COLUMNS($D6:H6))),"")} | J6: {=IFERROR("CTN " & INDEX('111 Wall_CTNR Schedule'!$E$8:$E$40,SMALL(IF(LEFT(SUBSTITUTE('111 Wall_CTNR Schedule'!$H$8:$H$40," ","")&",",LEN($C6&"")+1)=$C6&",",ROW('111 Wall_CTNR Schedule'!$H$8:$H$40)-ROW('111 Wall_CTNR Schedule'!$H$8)+1),COLUMNS($D6:I6))),"")} | K6: {=IFERROR("CTN " & INDEX('111 Wall_CTNR Schedule'!$E$8:$E$40,SMALL(IF(LEFT(SUBSTITUTE('111 Wall_CTNR Schedule'!$H$8:$H$40," ","")&",",LEN($C6&"")+1)=$C6&",",ROW('111 Wall_CTNR Schedule'!$H$8:$H$40)-ROW('111 Wall_CTNR Schedule'!$H$8)+1),COLUMNS($D6:J6))),"")} | L6: {=IFERROR("CTN " & INDEX('111 Wall_CTNR Schedule'!$E$8:$E$40,SMALL(IF(LEFT(SUBSTITUTE('111 Wall_CTNR Schedule'!$H$8:$H$40," ","")&",",LEN($C6&"")+1)=$C6&",",ROW('111 Wall_CTNR Schedule'!$H$8:$H$40)-ROW('111 Wall_CTNR Schedule'!$H$8)+1),COLUMNS($D6:K6))),"")} | ... N6: {=IFERROR("CTN " & INDEX('111 Wall_CTNR Schedule'!$E$8:$E$40,SMALL(IF(LEFT(SUBSTITUTE('111 Wall_CTNR Schedule'!$H$8:$H$40," ","")&",",LEN($C6&"")+1)=$C6&",",ROW('111 Wall_CTNR Schedule'!$H$8:$H$40)-ROW('111 Wall_CTNR Schedule'!$H$8)+1),COLUMNS($D6:M6))),"")}
